Workbook
Name Население: #REF!
Name домлн: #REF!
Name Баллы: #REF!

Sheet Итог без населения
B1: Номер вопроса
B2: Субъект РФ | C2: Коэф | D2: Сумма баллов | E2: Муж | F2: Жен | G2: 5х5 | H2: 3х3 | I2: Участие | J2: Призеры | K2: ='Показатели'!C2 -> Региональная федерация | L2: Маркетинг федерации | M2: ='Показатели'!C19 -> Общие критерии для региона | N2: Спортивные объекты | O2: Сборные команды России | R2: ='Показатели'!C31 -> Сборные команды России 5х5 | U2: Сборные команды России 3х3 | X2: Профессиональный баскетбол | Y2: Муж | Z2: Жен | AA2: ='Показатели'!C52 -> Профессиональный баскетбол 5х5 | AB2: Маркетиинг клубов | AC2: Муж | AD2: Жен | AE2: Участие | AH2: Призеры | AK2: Профессиональный баскетбол 3х3 | AL2: Муж | AM2: Жен | AN2: Участие | AQ2: Призеры | AT2: Резерв | AU2: ='Показатели'!C140 -> Резерв 5х5 | AV2: Отделения и проф воспитанники | AY2: Участие | BB2: Призеры | BE2: Резерв 3х3 | BH2: Участие | BK2: Призеры | BN2: Массовый баскетбол | BO2: ='Показатели'!C211 -> Массовый баскетбол 5х5 | BR2: Участие | BU2: Призеры | BX2: Локобаскет | CA2: КЭС-Баскет | CD2: АСБ | CG2: МЛБЛ | CJ2: ПР Ветераны | CM2: ='Показатели'!C552 -> Массовый баскетбол 3х3 | CP2: Участие | CS2: Призеры | CV2: Баскетбольные мероприятия | CW2: ='Показатели'!C377 -> Баскетбольные мероприятия 5х5 | CX2: ='Показатели'!C583 -> Баскетбольные мероприятия 3х3 | CY2: Судейство | CZ2: Судьи в поле | DA2: FIBA | DD2: ='Показатели'!C407 -> Судьи и тренеры 5х5 | DE2: Секретари и статистики | DF2: Судьи в поле и комиссары | DI2: FIBA | DM2: Комиссии | DN2: Судьи 3х3 | DO2: Судьи в поле | DP2: FIBA | DS2: Тихий баскетбол | DT2: Команды | DU2: Мероприятия | DV2: Интерактивный баскетбол | DW2: Участие | DX2: Призеры
B3: Подраздел | P3: Муж | Q3: Жен | S3: Муж | T3: Жен | V3: Муж | W3: Жен | AF3: Муж | AG3: Жен | AI3: Муж | AJ3: Жен | AO3: Муж | AP3: Жен | AR3: Муж | AS3: Жен | AW3: Муж | AX3: Жен | AZ3: Муж | BA3: Жен | BC3: Муж | BD3: Жен | BF3: Муж | BG3: Жен | BI3: Муж | BJ3: Жен | BL3: Муж | BM3: Жен | BP3: Муж | BQ3: Жен | BS3: Муж | BT3: Жен | BV3: Муж | BW3: Жен | BY3: Муж | BZ3: Жен | CB3: Муж | CC3: Жен | CE3: Муж | CF3: Жен | CH3: Муж | CI3: Жен | CK3: Муж | CL3: Жен | CN3: Муж | CO3: Жен | CQ3: Муж | CR3: Жен | CT3: Муж | CU3: Жен | DB3: Лицензии | DC3: Назначения | DG3: Судьи в поле | DH3: Комиссары | DJ3: Секретари и статитстики | DK3: Судьи в поле и комиссары | DL3: Назначения | DQ3: Лицензии | DR3: Назначения
A4: 1 | B4: ='Тест ответы'!B47 -> Москва | C4: 1 | D4: ='Баллы без населения'!D46 -> #REF! | E4: =SUMIF('Баллы без населения'!$E$3:DX$3,"муж",'Баллы без населения'!E46:DX46) -> #REF! | F4: =SUMIF('Баллы без населения'!$E$3:DX$3,"жен",'Баллы без населения'!E46:DX46) -> #REF! | G4: =SUM('Баллы без населения'!Z46:DK46,'Баллы без населения'!DP46:KE46,'Баллы без населения'!KV46:LL46) -> #REF! | H4: =SUM('Баллы без населения'!LM46:PB46,'Баллы без населения'!PY46:QJ46) -> 0 | I4: =SUM('Баллы без населения'!AZ46:BO46,'Баллы без населения'!DR46:DX46,'Баллы без населения'!FL46:FO46,'Баллы без населения'!GB46:GE46,'Баллы без населения'!GX46:HE46,'Баллы без населения'!IF46:IK46,'Баллы без населения'!IZ46:JG46,'Баллы без населения'!LU46:MG46,'Баллы без населения'!NW46:NZ46,'Баллы без населения'!OM46:OP46) -> 0 | J4: =SUM('Баллы без населения'!BP46:DK46,'Баллы без населения'!DY46:FK46,'Баллы без населения'!FP46:GA46,'Баллы без населения'!GF46:GQ46,'Баллы без населения'!HF46:HW46,'Баллы без населения'!IL46:IW46,'Баллы без населения'!JH46:KE46,'Баллы без населения'!MH46:NV46,'Баллы без населения'!OA46:OL46,'Баллы без населения'!OQ46:PB46) -> 0 | K4: =SUM('Баллы без населения'!E46:R46) -> 0 | L4: =SUM('Баллы без населения'!O46:R46) -> 0 | M4: =SUM('Баллы без населения'!S46:Y46) -> 0.1 | N4: =SUM('Баллы без населения'!T46:Y46) -> 0 | O4: =SUM('Баллы без населения'!Z46:AQ46,'Баллы без населения'!LM46:LT46) -> 0 | P4: =SUMIF('Баллы без населения'!$Z$3:$AQ$3,"муж",'Баллы без населения'!Z46:AQ46)+SUMIF('Баллы без населения'!$LM$3:$LT$3,"муж",'Баллы без населения'!LM46:LT46) -> 0 | Q4: =SUMIF('Баллы без населения'!$Z$3:$AQ$3,"жен",'Баллы без населения'!Z46:AQ46)+SUMIF('Баллы без населения'!$LM$3:$LT$3,"жен",'Баллы без населения'!LM46:LT46) -> 0 | R4: =SUM('Баллы без населения'!Z46:AQ46) -> 0 | S4: =SUM('Баллы без населения'!Z46:AH46) -> 0 | T4: =SUM('Баллы без населения'!AI46:AQ46) -> 0 | U4: =SUM('Баллы без населения'!LM46:LT46) -> 0 | V4: =SUM('Баллы без населения'!LM46:LP46) -> 0 | W4: =SUM('Баллы без населения'!LQ46:LT46) -> 0 | X4: =SUM('Баллы без населения'!AR46:DK46,'Баллы без населения'!LU46:NI46) -> 0 | Y4: ='Баллы без населения'!AR46+SUM('Баллы без населения'!AZ46:BH46)+SUM('Баллы без населения'!BP46:CP46)+SUM('Баллы без населения'!LU46:MC46,'Баллы без населения'!MH46:NI46) -> 0 | Z4: ='Баллы без населения'!AS46+SUM('Баллы без населения'!BI46:BO46)+SUM('Баллы без населения'!CQ46:DK46)+SUM('Баллы без населения'!MD46:MG46,'Баллы без населения'!NJ46:NV46,) -> 0 | AA4: =SUM('Баллы без населения'!AR46:DK46) -> 0 | AB4: =SUM('Баллы без населения'!AT46:AY46) -> 0 | AC4: ='Баллы без населения'!AR46+SUM('Баллы без населения'!AZ46:BH46)+SUM('Баллы без населения'!BP46:CP46) -> 0 | AD4: ='Баллы без населения'!AS46+SUM('Баллы без населения'!BI46:BO46)+SUM('Баллы без населения'!CQ46:DK46) -> 0 | AE4: =SUM('Баллы без населения'!AZ46:BO46) -> 0 | AF4: =SUM('Баллы без населения'!AZ46:BH46) -> 0 | AG4: =SUM('Баллы без населения'!BI46:BO46) -> 0 | AH4: =SUM('Баллы без населения'!BP46:DK46) -> 0 | AI4: =SUM('Баллы без населения'!BP46:CP46) -> 0 | AJ4: =SUM('Баллы без населения'!CQ46:DK46) -> 0 | AK4: =SUM('Баллы без населения'!LU46:NV46) -> 0 | AL4: =SUM('Баллы без населения'!LU46:MC46,'Баллы без населения'!MH46:NI46) -> 0 | AM4: =SUM('Баллы без населения'!MD46:MG46,'Баллы без населения'!NJ46:NV46,) -> 0 | AN4: =SUM('Баллы без населения'!LU46:MG46) -> 0 | AO4: =SUM('Баллы без населения'!LU46:MC46) -> 0 | AP4: =SUM('Баллы без населения'!MD46:MG46) -> 0 | AQ4: =SUM('Баллы без населения'!MH46:NV46) -> 0 | AR4: =SUM('Баллы без населения'!MH46:NI46) -> 0 | AS4: =SUM('Баллы без населения'!NJ46:NV46) -> 0 | AT4: =SUM('Баллы без населения'!DR46:FK46,'Баллы без населения'!NW46:OL46) -> 0 | AU4: =SUM('Баллы без населения'!DL46:FK46) -> #REF! | AV4: =SUM('Баллы без населения'!DL46:DQ46) -> #REF! | AW4: =SUM('Баллы без населения'!DR46:DU46)+SUM('Баллы без населения'!DY46:ES46) -> 0 | AX4: =SUM('Баллы без населения'!DV46:DX46)+SUM('Баллы без населения'!ET46:FK46) -> 0 | AY4: =SUM('Баллы без населения'!DR46:DX46) -> 0 | AZ4: =SUM('Баллы без населения'!DR46:DU46) -> 0 | BA4: =SUM('Баллы без населения'!DV46:DX46) -> 0 | BB4: =SUM('Баллы без населения'!DY46:FK46) -> 0 | BC4: =SUM('Баллы без населения'!DY46:ES46) -> 0 | BD4: =SUM('Баллы без населения'!ET46:FK46) -> 0 | BE4: =SUM('Баллы без населения'!NW46:OL46) -> 0 | BF4: =SUMIF('Баллы без населения'!NW44:OL44,"муж",'Баллы без населения'!NW46:OL46) -> 0 | BG4: =SUMIF('Баллы без населения'!NW44:OL44,"жен",'Баллы без населения'!NW46:OL46) -> 0 | BH4: =SUM('Баллы без населения'!NW46:NZ46) -> 0 | BI4: =SUMIF('Баллы без населения'!NW44:NZ44,"муж",'Баллы без населения'!NW46:NZ46) -> 0 | BJ4: =SUMIF('Баллы без населения'!NW44:NZ44,";ty",'Баллы без населения'!NW46:NZ46) -> 0 | BK4: =SUM('Баллы без населения'!OA46:OL46) -> 0 | BL4: =SUMIF('Баллы без населения'!OA44:OL44,"муж",'Баллы без населения'!OA46:OL46) -> 0 | BM4: =SUMIF('Баллы без населения'!OA44:OL44,"муж",'Баллы без населения'!OA46:OL46) -> 0 | BN4: =SUM('Баллы без населения'!FL46:KE46,'Баллы'!OM46:PB46) -> #REF! | BO4: =SUM('Баллы без населения'!FL46:KE46) -> #REF! | BP4: =SUM('Баллы без населения'!FL46:FM46,'Баллы без населения'!FP46:FU46,'Баллы без населения'!GB46:GC46,'Баллы без населения'!GF46:GK46,'Баллы без населения'!GR46:GT46,'Баллы без населения'!GX46:HA46,'Баллы без населения'!HF46:HN46,'Баллы без населения'!HX46,'Баллы без населения'!HZ46:IB46,'Баллы без населения'!IX46,'Баллы без населения'!IF46:IH46,'Баллы без населения'!IL46:IQ46,'Баллы без населения'!IZ46:JE46,'Баллы без населения'!JH46:JY46,) -> #REF! | BQ4: =SUM('Баллы без населения'!FN46:FO46,'Баллы без населения'!FV46:GA46,'Баллы без населения'!GD46:GE46,'Баллы без населения'!GL46:GQ46,'Баллы без населения'!GU46:GW46,'Баллы без населения'!HB46:HE46,'Баллы без населения'!HO46:HW46,'Баллы без населения'!HY46,'Баллы без населения'!IC46:IE46,'Баллы без населения'!II46:IK46,'Баллы без населения'!IR46:IW46,'Баллы без населения'!IY46,'Баллы без населения'!JF46:JG46,'Баллы без населения'!JZ46:KE46) -> #REF! | BR4: =SUM('Баллы без населения'!FL46:FO46,'Баллы без населения'!GB46:GE46,'Баллы без населения'!GX46:HE46,'Баллы без населения'!IF46:IK46,'Баллы без населения'!IZ46:JG46) -> 0 | BS4: =SUM('Баллы без населения'!FL46:FM46,'Баллы без населения'!GB46:GC46,'Баллы без населения'!GX46:HA46,'Баллы без населения'!IZ46:JE46) -> 0 | BT4: =SUM('Баллы без населения'!FN46:FO46,'Баллы без населения'!GD46:GE46,'Баллы без населения'!HB46:HE46,'Баллы без населения'!II46:IK46,'Баллы без населения'!JF46:JG46) -> 0 | BU4: =SUM('Баллы без населения'!FP46:GA46,'Баллы без населения'!GF46:GQ46,'Баллы без населения'!HF46:HW46,'Баллы без населения'!IL46:IW46,'Баллы без населения'!JH46:KE46) -> 0 | BV4: =SUM('Баллы без населения'!FP46:FU46,'Баллы без населения'!GF46:GK46,'Баллы без населения'!HF46:HN46,'Баллы без населения'!IL46:IQ46,'Баллы без населения'!JH46:JY46) -> 0 | BW4: =SUM('Баллы без населения'!FV46:GA46,'Баллы без населения'!GL46:GQ46,'Баллы без населения'!HO46:HW46,'Баллы без населения'!IL46:IW46,'Баллы без населения'!JZ46:KE46) -> 0 | BX4: =SUM('Баллы без населения'!FL46:GA46) -> 0 | BY4: =SUM('Баллы без населения'!FL46:FM46,'Баллы без населения'!FP46:FU46) -> 0 | BZ4: =SUM('Баллы без населения'!FN46:FO46,'Баллы без населения'!FV46:GA46) -> 0 | CA4: =SUM('Баллы без населения'!GB46:GQ46) -> 0 | CB4: =SUM('Баллы без населения'!GB46:GC46,'Баллы без населения'!GF46:GK46) -> 0 | CC4: =SUM('Баллы без населения'!GD46:GE46,'Баллы без населения'!GL46:GQ46) -> 0 | CD4: =SUM('Баллы без населения'!GR46:HY46) -> #REF! | CE4: =SUM('Баллы без населения'!GR46:GT46,'Баллы без населения'!GX46:HA46,'Баллы без населения'!HF46:HN46,'Баллы без населения'!HX46) -> #REF! | CF4: =SUM('Баллы без населения'!GU46:GW46,'Баллы без населения'!HB46:HE46,'Баллы без населения'!HO46:HW46,'Баллы без населения'!HY46) -> #REF! | CG4: =SUM('Баллы без населения'!HZ46:IY46) -> 0 | CH4: =SUM('Баллы без населения'!HZ46:IB46,'Баллы без населения'!IF46:IH46,'Баллы без населения'!IL46:IQ46,'Баллы без населения'!IX46) -> 0 | CI4: =SUM('Баллы без населения'!IC46:IE46,'Баллы без населения'!II46:IK46,'Баллы без населения'!IR46:IW46,'Баллы без населения'!IY46) -> 0 | CJ4: =SUM('Баллы без населения'!IZ46:KE46,) -> 0 | CK4: =SUM('Баллы без населения'!IZ46:JE46,'Баллы без населения'!JH46:JY46) -> 0 | CL4: =SUM('Баллы без населения'!JF46:JG46,'Баллы без населения'!JZ46:KE46) -> 0 | CM4: =SUM('Баллы без населения'!OM46:PB46) -> 0 | CN4: =SUMIF('Баллы без населения'!OM44:PB44,"муж",'Баллы без населения'!OM46:PB46) -> 0 | CO4: =SUMIF('Баллы без населения'!OM44:PB44,"жен",'Баллы без населения'!OM46:PB46) -> 0 | CP4: =SUM('Баллы без населения'!OM46:OP46) -> 0 | CQ4: =SUMIF('Баллы без населения'!OM44:OP44,"муж",'Баллы без населения'!OM46:OP46) -> 0 | CR4: =SUMIF('Баллы без населения'!OM44:OP44,"жен",'Баллы без населения'!OM46:OP46) -> 0 | CS4: =SUM('Баллы без населения'!OQ46:PB46) -> 0 | CT4: =SUMIF('Баллы без населения'!OQ44:PB44,"муж",'Баллы без населения'!OQ46:PB46) -> 0 | CU4: =SUMIF('Баллы без населения'!OQ44:PB44,"жен",'Баллы без населения'!OQ46:PB46) -> 0 | CV4: =SUM('Баллы'!KF46:KU46,'Баллы'!PC46:PX46) -> 0 | CW4: =SUM('Баллы без населения'!KF46:KU46) -> 0 | CX4: =SUM('Баллы без населения'!PC46:PX46) -> 0 | CY4: =SUM('Баллы без населения'!KV46:LL46,'Баллы без населения'!PZ46:QJ46) -> 0 | CZ4: =SUM('Баллы без населения'!KZ46:LB46,'Баллы без населения'!PZ46:QJ46) -> 0 | DA4: =SUM('Баллы без населения'!KX46:KY46,'Баллы без населения'!LB46:LC46,'Баллы без населения'!LF46:LG46,'Баллы без населения'!QE46:QJ46) -> 0 | DB4: =SUM('Баллы без населения'!KX46:KY46,'Баллы без населения'!LB46:LC46,'Баллы без населения'!LF46:LG46,'Баллы без населения'!QE46:QG46) -> 0 | DC4: =SUM('Баллы без населения'!LC46,'Баллы без населения'!LG46,'Баллы без населения'!QH46:QJ46) -> 0 | DD4: =SUM('Баллы без населения'!KV46:LL46) -> 0 | DE4: =SUM('Баллы без населения'!KV46:KY46) -> 0 | DF4: =SUM('Баллы без населения'!KZ46:LG46) -> 0 | DG4: =SUM('Баллы без населения'!KZ46:LB46) -> 0 | DH4: =SUM('Баллы без населения'!LD46:LF46) -> 0 | DI4: =SUM('Баллы без населения'!KX46:KY46,'Баллы без населения'!LB46:LC46,'Баллы без населения'!LF46:LG46) -> 0 | DJ4: =SUM('Баллы без населения'!KX46:KY46) -> 0 | DK4: =SUM('Баллы без населения'!LB46:LC46,'Баллы без населения'!LF46:LG46) -> 0 | DL4: =SUM('Баллы без населения'!LC46,'Баллы без населения'!LG46) -> 0 | DM4: =SUM('Баллы без населения'!LH46:LL46) -> 0 | DN4: =SUM('Баллы без населения'!PY46:QJ46) -> 0 | DO4: =SUM('Баллы без населения'!PZ46,'Баллы без населения'!QB46:QJ46) -> 0 | DP4: =SUM('Баллы без населения'!QE46:QJ46) -> 0 | DQ4: =SUM('Баллы без населения'!QE46:QG46) -> 0 | DR4: =SUM('Баллы без населения'!QH46:QJ46) -> 0 | DS4: =SUM('Баллы без населения'!QK46:QP46) -> #REF! | DT4: =SUM('Баллы без населения'!QL46:QM46,'Баллы без населения'!QP46) -> 0 | DU4: =SUM('Баллы без населения'!QN46) -> 0 | DV4: =SUM('Баллы без населения'!QQ46:QX46) -> 0 | DW4: =SUM('Баллы без населения'!QQ46:QR46) -> 0 | DX4: =SUM('Баллы без населения'!QS46:QX46) -> 0
A5: 2 | B5: ='Тест ответы'!B48 -> Московская область | C5: 1 | D5: ='Баллы без населения'!D47 -> #REF! | E5: =SUMIF('Баллы без населения'!$E$3:DX$3,"муж",'Баллы без населения'!E47:DX47) -> #REF! | F5: =SUMIF('Баллы без населения'!$E$3:DX$3,"жен",'Баллы без населения'!E47:DX47) -> #REF! | G5: =SUM('Баллы без населения'!Z47:DK47,'Баллы без населения'!DP47:KE47,'Баллы без населения'!KV47:LL47) -> #REF! | H5: =SUM('Баллы без населения'!LM47:PB47,'Баллы без населения'!PY47:QJ47) -> 0 | I5: =SUM('Баллы без населения'!AZ47:BO47,'Баллы без населения'!DR47:DX47,'Баллы без населения'!FL47:FO47,'Баллы без населения'!GB47:GE47,'Баллы без населения'!GX47:HE47,'Баллы без населения'!IF47:IK47,'Баллы без населения'!IZ47:JG47,'Баллы без населения'!LU47:MG47,'Баллы без населения'!NW47:NZ47,'Баллы без населения'!OM47:OP47) -> 0 | J5: =SUM('Баллы без населения'!BP47:DK47,'Баллы без населения'!DY47:FK47,'Баллы без населения'!FP47:GA47,'Баллы без населения'!GF47:GQ47,'Баллы без населения'!HF47:HW47,'Баллы без населения'!IL47:IW47,'Баллы без населения'!JH47:KE47,'Баллы без населения'!MH47:NV47,'Баллы без населения'!OA47:OL47,'Баллы без населения'!OQ47:PB47) -> 0 | K5: =SUM('Баллы без населения'!E47:R47) -> 0.1055 | L5: =SUM('Баллы без населения'!O47:R47) -> 0.1 | M5: =SUM('Баллы без населения'!S47:Y47) -> 0.1 | N5: =SUM('Баллы без населения'!T47:Y47) -> 0 | O5: =SUM('Баллы без населения'!Z47:AQ47,'Баллы без населения'!LM47:LT47) -> 0 | P5: =SUMIF('Баллы без населения'!$Z$3:$AQ$3,"муж",'Баллы без населения'!Z47:AQ47)+SUMIF('Баллы без населения'!$LM$3:$LT$3,"муж",'Баллы без населения'!LM47:LT47) -> 0 | Q5: =SUMIF('Баллы без населения'!$Z$3:$AQ$3,"жен",'Баллы без населения'!Z47:AQ47)+SUMIF('Баллы без населения'!$LM$3:$LT$3,"жен",'Баллы без населения'!LM47:LT47) -> 0 | R5: =SUM('Баллы без населения'!Z47:AQ47) -> 0 | S5: =SUM('Баллы без населения'!Z47:AH47) -> 0 | T5: =SUM('Баллы без населения'!AI47:AQ47) -> 0 | U5: =SUM('Баллы без населения'!LM47:LT47) -> 0 | V5: =SUM('Баллы без населения'!LM47:LP47) -> 0 | W5: =SUM('Баллы без населения'!LQ47:LT47) -> 0 | X5: =SUM('Баллы без населения'!AR47:DK47,'Баллы без населения'!LU47:NI47) -> 0 | Y5: ='Баллы без населения'!AR47+SUM('Баллы без населения'!AZ47:BH47)+SUM('Баллы без населения'!BP47:CP47)+SUM('Баллы без населения'!LU47:MC47,'Баллы без населения'!MH47:NI47) -> 0 | Z5: ='Баллы без населения'!AS47+SUM('Баллы без населения'!BI47:BO47)+SUM('Баллы без населения'!CQ47:DK47)+SUM('Баллы без населения'!MD47:MG47,'Баллы без населения'!NJ47:NV47,) -> 0 | AA5: =SUM('Баллы без населения'!AR47:DK47) -> 0 | AB5: =SUM('Баллы без населения'!AT47:AY47) -> 0 | AC5: ='Баллы без населения'!AR47+SUM('Баллы без населения'!AZ47:BH47)+SUM('Баллы без населения'!BP47:CP47) -> 0 | AD5: ='Баллы без населения'!AS47+SUM('Баллы без населения'!BI47:BO47)+SUM('Баллы без населения'!CQ47:DK47) -> 0 | AE5: =SUM('Баллы без населения'!AZ47:BO47) -> 0 | AF5: =SUM('Баллы без населения'!AZ47:BH47) -> 0 | AG5: =SUM('Баллы без населения'!BI47:BO47) -> 0 | AH5: =SUM('Баллы без населения'!BP47:DK47) -> 0 | AI5: =SUM('Баллы без населения'!BP47:CP47) -> 0 | AJ5: =SUM('Баллы без населения'!CQ47:DK47) -> 0 | AK5: =SUM('Баллы без населения'!LU47:NV47) -> 0 | AL5: =SUM('Баллы без населения'!LU47:MC47,'Баллы без населения'!MH47:NI47) -> 0 | AM5: =SUM('Баллы без населения'!MD47:MG47,'Баллы без населения'!NJ47:NV47,) -> 0 | AN5: =SUM('Баллы без населения'!LU47:MG47) -> 0 | AO5: =SUM('Баллы без населения'!LU47:MC47) -> 0 | AP5: =SUM('Баллы без населения'!MD47:MG47) -> 0 | AQ5: =SUM('Баллы без населения'!MH47:NV47) -> 0 | AR5: =SUM('Баллы без населения'!MH47:NI47) -> 0 | AS5: =SUM('Баллы без населения'!NJ47:NV47) -> 0 | AT5: =SUM('Баллы без населения'!DR47:FK47,'Баллы без населения'!NW47:OL47) -> 0 | AU5: =SUM('Баллы без населения'!DL47:FK47) -> #REF! | AV5: =SUM('Баллы без населения'!DL47:DQ47) -> #REF! | AW5: =SUM('Баллы без населения'!DR47:DU47)+SUM('Баллы без населения'!DY47:ES47) -> 0 | AX5: =SUM('Баллы без населения'!DV47:DX47)+SUM('Баллы без населения'!ET47:FK47) -> 0 | AY5: =SUM('Баллы без населения'!DR47:DX47) -> 0 | AZ5: =SUM('Баллы без населения'!DR47:DU47) -> 0 | BA5: =SUM('Баллы без населения'!DV47:DX47) -> 0 | BB5: =SUM('Баллы без населения'!DY47:FK47) -> 0 | BC5: =SUM('Баллы без населения'!DY47:ES47) -> 0 | BD5: =SUM('Баллы без населения'!ET47:FK47) -> 0 | BE5: =SUM('Баллы без населения'!NW47:OL47) -> 0 | BF5: =SUMIF('Баллы без населения'!NW45:OL45,"муж",'Баллы без населения'!NW47:OL47) -> 0 | BG5: =SUMIF('Баллы без населения'!NW45:OL45,"жен",'Баллы без населения'!NW47:OL47) -> 0 | BH5: =SUM('Баллы без населения'!NW47:NZ47) -> 0 | BI5: =SUMIF('Баллы без населения'!NW45:NZ45,"муж",'Баллы без населения'!NW47:NZ47) -> 0 | BJ5: =SUMIF('Баллы без населения'!NW45:NZ45,";ty",'Баллы без населения'!NW47:NZ47) -> 0 | BK5: =SUM('Баллы без населения'!OA47:OL47) -> 0 | BL5: =SUMIF('Баллы без населения'!OA45:OL45,"муж",'Баллы без населения'!OA47:OL47) -> 0 | BM5: =SUMIF('Баллы без населения'!OA45:OL45,"муж",'Баллы без населения'!OA47:OL47) -> 0 | BN5: =SUM('Баллы без населения'!FL47:KE47,'Баллы'!OM47:PB47) -> #REF! | BO5: =SUM('Баллы без населения'!FL47:KE47) -> #REF! | BP5: =SUM('Баллы без населения'!FL47:FM47,'Баллы без населения'!FP47:FU47,'Баллы без населения'!GB47:GC47,'Баллы без населения'!GF47:GK47,'Баллы без населения'!GR47:GT47,'Баллы без населения'!GX47:HA47,'Баллы без населения'!HF47:HN47,'Баллы без населения'!HX47,'Баллы без населения'!HZ47:IB47,'Баллы без населения'!IX47,'Баллы без населения'!IF47:IH47,'Баллы без населения'!IL47:IQ47,'Баллы без населения'!IZ47:JE47,'Баллы без населения'!JH47:JY47,) -> #REF! | BQ5: =SUM('Баллы без населения'!FN47:FO47,'Баллы без населения'!FV47:GA47,'Баллы без населения'!GD47:GE47,'Баллы без населения'!GL47:GQ47,'Баллы без населения'!GU47:GW47,'Баллы без населения'!HB47:HE47,'Баллы без населения'!HO47:HW47,'Баллы без населения'!HY47,'Баллы без населения'!IC47:IE47,'Баллы без населения'!II47:IK47,'Баллы без населения'!IR47:IW47,'Баллы без населения'!IY47,'Баллы без населения'!JF47:JG47,'Баллы без населения'!JZ47:KE47) -> #REF! | BR5: =SUM('Баллы без населения'!FL47:FO47,'Баллы без населения'!GB47:GE47,'Баллы без населения'!GX47:HE47,'Баллы без населения'!IF47:IK47,'Баллы без населения'!IZ47:JG47) -> 0 | BS5: =SUM('Баллы без населения'!FL47:FM47,'Баллы без населения'!GB47:GC47,'Баллы без населения'!GX47:HA47,'Баллы без населения'!IZ47:JE47) -> 0 | BT5: =SUM('Баллы без населения'!FN47:FO47,'Баллы без населения'!GD47:GE47,'Баллы без населения'!HB47:HE47,'Баллы без населения'!II47:IK47,'Баллы без населения'!JF47:JG47) -> 0 | BU5: =SUM('Баллы без населения'!FP47:GA47,'Баллы без населения'!GF47:GQ47,'Баллы без населения'!HF47:HW47,'Баллы без населения'!IL47:IW47,'Баллы без населения'!JH47:KE47) -> 0 | BV5: =SUM('Баллы без населения'!FP47:FU47,'Баллы без населения'!GF47:GK47,'Баллы без населения'!HF47:HN47,'Баллы без населения'!IL47:IQ47,'Баллы без населения'!JH47:JY47) -> 0 | BW5: =SUM('Баллы без населения'!FV47:GA47,'Баллы без населения'!GL47:GQ47,'Баллы без населения'!HO47:HW47,'Баллы без населения'!IL47:IW47,'Баллы без населения'!JZ47:KE47) -> 0 | BX5: =SUM('Баллы без населения'!FL47:GA47) -> 0 | BY5: =SUM('Баллы без населения'!FL47:FM47,'Баллы без населения'!FP47:FU47) -> 0 | BZ5: =SUM('Баллы без населения'!FN47:FO47,'Баллы без населения'!FV47:GA47) -> 0 | CA5: =SUM('Баллы без населения'!GB47:GQ47) -> 0 | CB5: =SUM('Баллы без населения'!GB47:GC47,'Баллы без населения'!GF47:GK47) -> 0 | CC5: =SUM('Баллы без населения'!GD47:GE47,'Баллы без населения'!GL47:GQ47) -> 0 | CD5: =SUM('Баллы без населения'!GR47:HY47) -> #REF! | CE5: =SUM('Баллы без населения'!GR47:GT47,'Баллы без населения'!GX47:HA47,'Баллы без населения'!HF47:HN47,'Баллы без населения'!HX47) -> #REF! | CF5: =SUM('Баллы без населения'!GU47:GW47,'Баллы без населения'!HB47:HE47,'Баллы без населения'!HO47:HW47,'Баллы без населения'!HY47) -> #REF! | CG5: =SUM('Баллы без населения'!HZ47:IY47) -> 0 | CH5: =SUM('Баллы без населения'!HZ47:IB47,'Баллы без населения'!IF47:IH47,'Баллы без населения'!IL47:IQ47,'Баллы без населения'!IX47) -> 0 | CI5: =SUM('Баллы без населения'!IC47:IE47,'Баллы без населения'!II47:IK47,'Баллы без населения'!IR47:IW47,'Баллы без населения'!IY47) -> 0 | CJ5: =SUM('Баллы без населения'!IZ47:KE47,) -> 0 | CK5: =SUM('Баллы без населения'!IZ47:JE47,'Баллы без населения'!JH47:JY47) -> 0 | CL5: =SUM('Баллы без населения'!JF47:JG47,'Баллы без населения'!JZ47:KE47) -> 0 | CM5: =SUM('Баллы без населения'!OM47:PB47) -> 0 | CN5: =SUMIF('Баллы без населения'!OM45:PB45,"муж",'Баллы без населения'!OM47:PB47) -> 0 | CO5: =SUMIF('Баллы без населения'!OM45:PB45,"жен",'Баллы без населения'!OM47:PB47) -> 0 | CP5: =SUM('Баллы без населения'!OM47:OP47) -> 0 | CQ5: =SUMIF('Баллы без населения'!OM45:OP45,"муж",'Баллы без населения'!OM47:OP47) -> 0 | CR5: =SUMIF('Баллы без населения'!OM45:OP45,"жен",'Баллы без населения'!OM47:OP47) -> 0 | CS5: =SUM('Баллы без населения'!OQ47:PB47) -> 0 | CT5: =SUMIF('Баллы без населения'!OQ45:PB45,"муж",'Баллы без населения'!OQ47:PB47) -> 0 | CU5: =SUMIF('Баллы без населения'!OQ45:PB45,"жен",'Баллы без населения'!OQ47:PB47) -> 0 | CV5: =SUM('Баллы'!KF47:KU47,'Баллы'!PC47:PX47) -> 0 | CW5: =SUM('Баллы без населения'!KF47:KU47) -> 0 | CX5: =SUM('Баллы без населения'!PC47:PX47) -> 0 | CY5: =SUM('Баллы без населения'!KV47:LL47,'Баллы без населения'!PZ47:QJ47) -> 0 | CZ5: =SUM('Баллы без населения'!KZ47:LB47,'Баллы без населения'!PZ47:QJ47) -> 0 | DA5: =SUM('Баллы без населения'!KX47:KY47,'Баллы без населения'!LB47:LC47,'Баллы без населения'!LF47:LG47,'Баллы без населения'!QE47:QJ47) -> 0 | DB5: =SUM('Баллы без населения'!KX47:KY47,'Баллы без населения'!LB47:LC47,'Баллы без населения'!LF47:LG47,'Баллы без населения'!QE47:QG47) -> 0 | DC5: =SUM('Баллы без населения'!LC47,'Баллы без населения'!LG47,'Баллы без населения'!QH47:QJ47) -> 0 | DD5: =SUM('Баллы без населения'!KV47:LL47) -> 0 | DE5: =SUM('Баллы без населения'!KV47:KY47) -> 0 | DF5: =SUM('Баллы без населения'!KZ47:LG47) -> 0 | DG5: =SUM('Баллы без населения'!KZ47:LB47) -> 0 | DH5: =SUM('Баллы без населения'!LD47:LF47) -> 0 | DI5: =SUM('Баллы без населения'!KX47:KY47,'Баллы без населения'!LB47:LC47,'Баллы без населения'!LF47:LG47) -> 0 | DJ5: =SUM('Баллы без населения'!KX47:KY47) -> 0 | DK5: =SUM('Баллы без населения'!LB47:LC47,'Баллы без населения'!LF47:LG47) -> 0 | DL5: =SUM('Баллы без населения'!LC47,'Баллы без населения'!LG47) -> 0 | DM5: =SUM('Баллы без населения'!LH47:LL47) -> 0 | DN5: =SUM('Баллы без населения'!PY47:QJ47) -> 0 | DO5: =SUM('Баллы без населения'!PZ47,'Баллы без населения'!QB47:QJ47) -> 0 | DP5: =SUM('Баллы без населения'!QE47:QJ47) -> 0 | DQ5: =SUM('Баллы без населения'!QE47:QG47) -> 0 | DR5: =SUM('Баллы без населения'!QH47:QJ47) -> 0 | DS5: =SUM('Баллы без населения'!QK47:QP47) -> #REF! | DT5: =SUM('Баллы без населения'!QL47:QM47,'Баллы без населения'!QP47) -> 0 | DU5: =SUM('Баллы без населения'!QN47) -> 0 | DV5: =SUM('Баллы без населения'!QQ47:QX47) -> 0 | DW5: =SUM('Баллы без населения'!QQ47:QR47) -> 0 | DX5: =SUM('Баллы без населения'!QS47:QX47) -> 0
A6: 3 | B6: ='Тест ответы'!B64 -> Санкт-Петербург | C6: 1 | D6: ='Баллы без населения'!D63 -> #REF! | E6: =SUMIF('Баллы без населения'!$E$3:DX$3,"муж",'Баллы без населения'!E63:DX63) -> #REF! | F6: =SUMIF('Баллы без населения'!$E$3:DX$3,"жен",'Баллы без населения'!E63:DX63) -> #REF! | G6: =SUM('Баллы без населения'!Z63:DK63,'Баллы без населения'!DP63:KE63,'Баллы без населения'!KV63:LL63) -> #REF! | H6: =SUM('Баллы без населения'!LM63:PB63,'Баллы без населения'!PY63:QJ63) -> 0 | I6: =SUM('Баллы без населения'!AZ63:BO63,'Баллы без населения'!DR63:DX63,'Баллы без населения'!FL63:FO63,'Баллы без населения'!GB63:GE63,'Баллы без населения'!GX63:HE63,'Баллы без населения'!IF63:IK63,'Баллы без населения'!IZ63:JG63,'Баллы без населения'!LU63:MG63,'Баллы без населения'!NW63:NZ63,'Баллы без населения'!OM63:OP63) -> 0 | J6: =SUM('Баллы без населения'!BP63:DK63,'Баллы без населения'!DY63:FK63,'Баллы без населения'!FP63:GA63,'Баллы без населения'!GF63:GQ63,'Баллы без населения'!HF63:HW63,'Баллы без населения'!IL63:IW63,'Баллы без населения'!JH63:KE63,'Баллы без населения'!MH63:NV63,'Баллы без населения'!OA63:OL63,'Баллы без населения'!OQ63:PB63) -> 0 | K6: =SUM('Баллы без населения'!E63:R63) -> 0.1235 | L6: =SUM('Баллы без населения'!O63:R63) -> 0.09 | M6: =SUM('Баллы без населения'!S63:Y63) -> 0.1 | N6: =SUM('Баллы без населения'!T63:Y63) -> 0 | O6: =SUM('Баллы без населения'!Z63:AQ63,'Баллы без населения'!LM63:LT63) -> 0 | P6: =SUMIF('Баллы без населения'!$Z$3:$AQ$3,"муж",'Баллы без населения'!Z63:AQ63)+SUMIF('Баллы без населения'!$LM$3:$LT$3,"муж",'Баллы без населения'!LM63:LT63) -> 0 | Q6: =SUMIF('Баллы без населения'!$Z$3:$AQ$3,"жен",'Баллы без населения'!Z63:AQ63)+SUMIF('Баллы без населения'!$LM$3:$LT$3,"жен",'Баллы без населения'!LM63:LT63) -> 0 | R6: =SUM('Баллы без населения'!Z63:AQ63) -> 0 | S6: =SUM('Баллы без населения'!Z63:AH63) -> 0 | T6: =SUM('Баллы без населения'!AI63:AQ63) -> 0 | U6: =SUM('Баллы без населения'!LM63:LT63) -> 0 | V6: =SUM('Баллы без населения'!LM63:LP63) -> 0 | W6: =SUM('Баллы без населения'!LQ63:LT63) -> 0 | X6: =SUM('Баллы без населения'!AR63:DK63,'Баллы без населения'!LU63:NI63) -> 0 | Y6: ='Баллы без населения'!AR63+SUM('Баллы без населения'!AZ63:BH63)+SUM('Баллы без населения'!BP63:CP63)+SUM('Баллы без населения'!LU63:MC63,'Баллы без населения'!MH63:NI63) -> 0 | Z6: ='Баллы без населения'!AS63+SUM('Баллы без населения'!BI63:BO63)+SUM('Баллы без населения'!CQ63:DK63)+SUM('Баллы без населения'!MD63:MG63,'Баллы без населения'!NJ63:NV63,) -> 0 | AA6: =SUM('Баллы без населения'!AR63:DK63) -> 0 | AB6: =SUM('Баллы без населения'!AT63:AY63) -> 0 | AC6: ='Баллы без населения'!AR63+SUM('Баллы без населения'!AZ63:BH63)+SUM('Баллы без населения'!BP63:CP63) -> 0 | AD6: ='Баллы без населения'!AS63+SUM('Баллы без населения'!BI63:BO63)+SUM('Баллы без населения'!CQ63:DK63) -> 0 | AE6: =SUM('Баллы без населения'!AZ63:BO63) -> 0 | AF6: =SUM('Баллы без населения'!AZ63:BH63) -> 0 | AG6: =SUM('Баллы без населения'!BI63:BO63) -> 0 | AH6: =SUM('Баллы без населения'!BP63:DK63) -> 0 | AI6: =SUM('Баллы без населения'!BP63:CP63) -> 0 | AJ6: =SUM('Баллы без населения'!CQ63:DK63) -> 0 | AK6: =SUM('Баллы без населения'!LU63:NV63) -> 0 | AL6: =SUM('Баллы без населения'!LU63:MC63,'Баллы без населения'!MH63:NI63) -> 0 | AM6: =SUM('Баллы без населения'!MD63:MG63,'Баллы без населения'!NJ63:NV63,) -> 0 | AN6: =SUM('Баллы без населения'!LU63:MG63) -> 0 | AO6: =SUM('Баллы без населения'!LU63:MC63) -> 0 | AP6: =SUM('Баллы без населения'!MD63:MG63) -> 0 | AQ6: =SUM('Баллы без населения'!MH63:NV63) -> 0 | AR6: =SUM('Баллы без населения'!MH63:NI63) -> 0 | AS6: =SUM('Баллы без населения'!NJ63:NV63) -> 0 | AT6: =SUM('Баллы без населения'!DR63:FK63,'Баллы без населения'!NW63:OL63) -> 0 | AU6: =SUM('Баллы без населения'!DL63:FK63) -> #REF! | AV6: =SUM('Баллы без населения'!DL63:DQ63) -> #REF! | AW6: =SUM('Баллы без населения'!DR63:DU63)+SUM('Баллы без населения'!DY63:ES63) -> 0 | AX6: =SUM('Баллы без населения'!DV63:DX63)+SUM('Баллы без населения'!ET63:FK63) -> 0 | AY6: =SUM('Баллы без населения'!DR63:DX63) -> 0 | AZ6: =SUM('Баллы без населения'!DR63:DU63) -> 0 | BA6: =SUM('Баллы без населения'!DV63:DX63) -> 0 | BB6: =SUM('Баллы без населения'!DY63:FK63) -> 0 | BC6: =SUM('Баллы без населения'!DY63:ES63) -> 0 | BD6: =SUM('Баллы без населения'!ET63:FK63) -> 0 | BE6: =SUM('Баллы без населения'!NW63:OL63) -> 0 | BF6: =SUMIF('Баллы без населения'!NW61:OL61,"муж",'Баллы без населения'!NW63:OL63) -> 0 | BG6: =SUMIF('Баллы без населения'!NW61:OL61,"жен",'Баллы без населения'!NW63:OL63) -> 0 | BH6: =SUM('Баллы без населения'!NW63:NZ63) -> 0 | BI6: =SUMIF('Баллы без населения'!NW61:NZ61,"муж",'Баллы без населения'!NW63:NZ63) -> 0 | BJ6: =SUMIF('Баллы без населения'!NW61:NZ61,";ty",'Баллы без населения'!NW63:NZ63) -> 0 | BK6: =SUM('Баллы без населения'!OA63:OL63) -> 0 | BL6: =SUMIF('Баллы без населения'!OA61:OL61,"муж",'Баллы без населения'!OA63:OL63) -> 0 | BM6: =SUMIF('Баллы без населения'!OA61:OL61,"муж",'Баллы без населения'!OA63:OL63) -> 0 | BN6: =SUM('Баллы без населения'!FL63:KE63,'Баллы'!OM63:PB63) -> #REF! | BO6: =SUM('Баллы без населения'!FL63:KE63) -> #REF! | BP6: =SUM('Баллы без населения'!FL63:FM63,'Баллы без населения'!FP63:FU63,'Баллы без населения'!GB63:GC63,'Баллы без населения'!GF63:GK63,'Баллы без населения'!GR63:GT63,'Баллы без населения'!GX63:HA63,'Баллы без населения'!HF63:HN63,'Баллы без населения'!HX63,'Баллы без населения'!HZ63:IB63,'Баллы без населения'!IX63,'Баллы без населения'!IF63:IH63,'Баллы без населения'!IL63:IQ63,'Баллы без населения'!IZ63:JE63,'Баллы без населения'!JH63:JY63,) -> #REF! | BQ6: =SUM('Баллы без населения'!FN63:FO63,'Баллы без населения'!FV63:GA63,'Баллы без населения'!GD63:GE63,'Баллы без населения'!GL63:GQ63,'Баллы без населения'!GU63:GW63,'Баллы без населения'!HB63:HE63,'Баллы без населения'!HO63:HW63,'Баллы без населения'!HY63,'Баллы без населения'!IC63:IE63,'Баллы без населения'!II63:IK63,'Баллы без населения'!IR63:IW63,'Баллы без населения'!IY63,'Баллы без населения'!JF63:JG63,'Баллы без населения'!JZ63:KE63) -> #REF! | BR6: =SUM('Баллы без населения'!FL63:FO63,'Баллы без населения'!GB63:GE63,'Баллы без населения'!GX63:HE63,'Баллы без населения'!IF63:IK63,'Баллы без населения'!IZ63:JG63) -> 0 | BS6: =SUM('Баллы без населения'!FL63:FM63,'Баллы без населения'!GB63:GC63,'Баллы без населения'!GX63:HA63,'Баллы без населения'!IZ63:JE63) -> 0 | BT6: =SUM('Баллы без населения'!FN63:FO63,'Баллы без населения'!GD63:GE63,'Баллы без населения'!HB63:HE63,'Баллы без населения'!II63:IK63,'Баллы без населения'!JF63:JG63) -> 0 | BU6: =SUM('Баллы без населения'!FP63:GA63,'Баллы без населения'!GF63:GQ63,'Баллы без населения'!HF63:HW63,'Баллы без населения'!IL63:IW63,'Баллы без населения'!JH63:KE63) -> 0 | BV6: =SUM('Баллы без населения'!FP63:FU63,'Баллы без населения'!GF63:GK63,'Баллы без населения'!HF63:HN63,'Баллы без населения'!IL63:IQ63,'Баллы без населения'!JH63:JY63) -> 0 | BW6: =SUM('Баллы без населения'!FV63:GA63,'Баллы без населения'!GL63:GQ63,'Баллы без населения'!HO63:HW63,'Баллы без населения'!IL63:IW63,'Баллы без населения'!JZ63:KE63) -> 0 | BX6: =SUM('Баллы без населения'!FL63:GA63) -> 0 | BY6: =SUM('Баллы без населения'!FL63:FM63,'Баллы без населения'!FP63:FU63) -> 0 | BZ6: =SUM('Баллы без населения'!FN63:FO63,'Баллы без населения'!FV63:GA63) -> 0 | CA6: =SUM('Баллы без населения'!GB63:GQ63) -> 0 | CB6: =SUM('Баллы без населения'!GB63:GC63,'Баллы без населения'!GF63:GK63) -> 0 | CC6: =SUM('Баллы без населения'!GD63:GE63,'Баллы без населения'!GL63:GQ63) -> 0 | CD6: =SUM('Баллы без населения'!GR63:HY63) -> #REF! | CE6: =SUM('Баллы без населения'!GR63:GT63,'Баллы без населения'!GX63:HA63,'Баллы без населения'!HF63:HN63,'Баллы без населения'!HX63) -> #REF! | CF6: =SUM('Баллы без населения'!GU63:GW63,'Баллы без населения'!HB63:HE63,'Баллы без населения'!HO63:HW63,'Баллы без населения'!HY63) -> #REF! | CG6: =SUM('Баллы без населения'!HZ63:IY63) -> 0 | CH6: =SUM('Баллы без населения'!HZ63:IB63,'Баллы без населения'!IF63:IH63,'Баллы без населения'!IL63:IQ63,'Баллы без населения'!IX63) -> 0 | CI6: =SUM('Баллы без населения'!IC63:IE63,'Баллы без населения'!II63:IK63,'Баллы без населения'!IR63:IW63,'Баллы без населения'!IY63) -> 0 | CJ6: =SUM('Баллы без населения'!IZ63:KE63,) -> 0 | CK6: =SUM('Баллы без населения'!IZ63:JE63,'Баллы без населения'!JH63:JY63) -> 0 | CL6: =SUM('Баллы без населения'!JF63:JG63,'Баллы без населения'!JZ63:KE63) -> 0 | CM6: =SUM('Баллы без населения'!OM63:PB63) -> 0 | CN6: =SUMIF('Баллы без населения'!OM61:PB61,"муж",'Баллы без населения'!OM63:PB63) -> 0 | CO6: =SUMIF('Баллы без населения'!OM61:PB61,"жен",'Баллы без населения'!OM63:PB63) -> 0 | CP6: =SUM('Баллы без населения'!OM63:OP63) -> 0 | CQ6: =SUMIF('Баллы без населения'!OM61:OP61,"муж",'Баллы без населения'!OM63:OP63) -> 0 | CR6: =SUMIF('Баллы без населения'!OM61:OP61,"жен",'Баллы без населения'!OM63:OP63) -> 0 | CS6: =SUM('Баллы без населения'!OQ63:PB63) -> 0 | CT6: =SUMIF('Баллы без населения'!OQ61:PB61,"муж",'Баллы без населения'!OQ63:PB63) -> 0 | CU6: =SUMIF('Баллы без населения'!OQ61:PB61,"жен",'Баллы без населения'!OQ63:PB63) -> 0 | CV6: =SUM('Баллы'!KF63:KU63,'Баллы'!PC63:PX63) -> 0 | CW6: =SUM('Баллы без населения'!KF63:KU63) -> 0 | CX6: =SUM('Баллы без населения'!PC63:PX63) -> 0 | CY6: =SUM('Баллы без населения'!KV63:LL63,'Баллы без населения'!PZ63:QJ63) -> 0 | CZ6: =SUM('Баллы без населения'!KZ63:LB63,'Баллы без населения'!PZ63:QJ63) -> 0 | DA6: =SUM('Баллы без населения'!KX63:KY63,'Баллы без населения'!LB63:LC63,'Баллы без населения'!LF63:LG63,'Баллы без населения'!QE63:QJ63) -> 0 | DB6: =SUM('Баллы без населения'!KX63:KY63,'Баллы без населения'!LB63:LC63,'Баллы без населения'!LF63:LG63,'Баллы без населения'!QE63:QG63) -> 0 | DC6: =SUM('Баллы без населения'!LC63,'Баллы без населения'!LG63,'Баллы без населения'!QH63:QJ63) -> 0 | DD6: =SUM('Баллы без населения'!KV63:LL63) -> 0 | DE6: =SUM('Баллы без населения'!KV63:KY63) -> 0 | DF6: =SUM('Баллы без населения'!KZ63:LG63) -> 0 | DG6: =SUM('Баллы без населения'!KZ63:LB63) -> 0 | DH6: =SUM('Баллы без населения'!LD63:LF63) -> 0 | DI6: =SUM('Баллы без населения'!KX63:KY63,'Баллы без населения'!LB63:LC63,'Баллы без населения'!LF63:LG63) -> 0 | DJ6: =SUM('Баллы без населения'!KX63:KY63) -> 0 | DK6: =SUM('Баллы без населения'!LB63:LC63,'Баллы без населения'!LF63:LG63) -> 0 | DL6: =SUM('Баллы без населения'!LC63,'Баллы без населения'!LG63) -> 0 | DM6: =SUM('Баллы без населения'!LH63:LL63) -> 0 | DN6: =SUM('Баллы без населения'!PY63:QJ63) -> 0 | DO6: =SUM('Баллы без населения'!PZ63,'Баллы без населения'!QB63:QJ63) -> 0 | DP6: =SUM('Баллы без населения'!QE63:QJ63) -> 0 | DQ6: =SUM('Баллы без населения'!QE63:QG63) -> 0 | DR6: =SUM('Баллы без населения'!QH63:QJ63) -> 0 | DS6: =SUM('Баллы без населения'!QK63:QP63) -> #REF! | DT6: =SUM('Баллы без населения'!QL63:QM63,'Баллы без населения'!QP63) -> 0 | DU6: =SUM('Баллы без населения'!QN63) -> 0 | DV6: =SUM('Баллы без населения'!QQ63:QX63) -> 0 | DW6: =SUM('Баллы без населения'!QQ63:QR63) -> 0 | DX6: =SUM('Баллы без населения'!QS63:QX63) -> 0
A7: 4 | B7: ='Тест ответы'!B68 -> Свердловская область | C7: 1 | D7: ='Баллы без населения'!D67 -> #REF! | E7: =SUMIF('Баллы без населения'!$E$3:DX$3,"муж",'Баллы без населения'!E67:DX67) -> #REF! | F7: =SUMIF('Баллы без населения'!$E$3:DX$3,"жен",'Баллы без населения'!E67:DX67) -> #REF! | G7: =SUM('Баллы без населения'!Z67:DK67,'Баллы без населения'!DP67:KE67,'Баллы без населения'!KV67:LL67) -> #REF! | H7: =SUM('Баллы без населения'!LM67:PB67,'Баллы без населения'!PY67:QJ67) -> 0 | I7: =SUM('Баллы без населения'!AZ67:BO67,'Баллы без населения'!DR67:DX67,'Баллы без населения'!FL67:FO67,'Баллы без населения'!GB67:GE67,'Баллы без населения'!GX67:HE67,'Баллы без населения'!IF67:IK67,'Баллы без населения'!IZ67:JG67,'Баллы без населения'!LU67:MG67,'Баллы без населения'!NW67:NZ67,'Баллы без населения'!OM67:OP67) -> 0 | J7: =SUM('Баллы без населения'!BP67:DK67,'Баллы без населения'!DY67:FK67,'Баллы без населения'!FP67:GA67,'Баллы без населения'!GF67:GQ67,'Баллы без населения'!HF67:HW67,'Баллы без населения'!IL67:IW67,'Баллы без населения'!JH67:KE67,'Баллы без населения'!MH67:NV67,'Баллы без населения'!OA67:OL67,'Баллы без населения'!OQ67:PB67) -> 0 | K7: =SUM('Баллы без населения'!E67:R67) -> 0.1955 | L7: =SUM('Баллы без населения'!O67:R67) -> 0.19 | M7: =SUM('Баллы без населения'!S67:Y67) -> 0.1 | N7: =SUM('Баллы без населения'!T67:Y67) -> 0 | O7: =SUM('Баллы без населения'!Z67:AQ67,'Баллы без населения'!LM67:LT67) -> 0 | P7: =SUMIF('Баллы без населения'!$Z$3:$AQ$3,"муж",'Баллы без населения'!Z67:AQ67)+SUMIF('Баллы без населения'!$LM$3:$LT$3,"муж",'Баллы без населения'!LM67:LT67) -> 0 | Q7: =SUMIF('Баллы без населения'!$Z$3:$AQ$3,"жен",'Баллы без населения'!Z67:AQ67)+SUMIF('Баллы без населения'!$LM$3:$LT$3,"жен",'Баллы без населения'!LM67:LT67) -> 0 | R7: =SUM('Баллы без населения'!Z67:AQ67) -> 0 | S7: =SUM('Баллы без населения'!Z67:AH67) -> 0 | T7: =SUM('Баллы без населения'!AI67:AQ67) -> 0 | U7: =SUM('Баллы без населения'!LM67:LT67) -> 0 | V7: =SUM('Баллы без населения'!LM67:LP67) -> 0 | W7: =SUM('Баллы без населения'!LQ67:LT67) -> 0 | X7: =SUM('Баллы без населения'!AR67:DK67,'Баллы без населения'!LU67:NI67) -> 0 | Y7: ='Баллы без населения'!AR67+SUM('Баллы без населения'!AZ67:BH67)+SUM('Баллы без населения'!BP67:CP67)+SUM('Баллы без населения'!LU67:MC67,'Баллы без населения'!MH67:NI67) -> 0 | Z7: ='Баллы без населения'!AS67+SUM('Баллы без населения'!BI67:BO67)+SUM('Баллы без населения'!CQ67:DK67)+SUM('Баллы без населения'!MD67:MG67,'Баллы без населения'!NJ67:NV67,) -> 0 | AA7: =SUM('Баллы без населения'!AR67:DK67) -> 0 | AB7: =SUM('Баллы без населения'!AT67:AY67) -> 0 | AC7: ='Баллы без населения'!AR67+SUM('Баллы без населения'!AZ67:BH67)+SUM('Баллы без населения'!BP67:CP67) -> 0 | AD7: ='Баллы без населения'!AS67+SUM('Баллы без населения'!BI67:BO67)+SUM('Баллы без населения'!CQ67:DK67) -> 0 | AE7: =SUM('Баллы без населения'!AZ67:BO67) -> 0 | AF7: =SUM('Баллы без населения'!AZ67:BH67) -> 0 | AG7: =SUM('Баллы без населения'!BI67:BO67) -> 0 | AH7: =SUM('Баллы без населения'!BP67:DK67) -> 0 | AI7: =SUM('Баллы без населения'!BP67:CP67) -> 0 | AJ7: =SUM('Баллы без населения'!CQ67:DK67) -> 0 | AK7: =SUM('Баллы без населения'!LU67:NV67) -> 0 | AL7: =SUM('Баллы без населения'!LU67:MC67,'Баллы без населения'!MH67:NI67) -> 0 | AM7: =SUM('Баллы без населения'!MD67:MG67,'Баллы без населения'!NJ67:NV67,) -> 0 | AN7: =SUM('Баллы без населения'!LU67:MG67) -> 0 | AO7: =SUM('Баллы без населения'!LU67:MC67) -> 0 | AP7: =SUM('Баллы без населения'!MD67:MG67) -> 0 | AQ7: =SUM('Баллы без населения'!MH67:NV67) -> 0 | AR7: =SUM('Баллы без населения'!MH67:NI67) -> 0 | AS7: =SUM('Баллы без населения'!NJ67:NV67) -> 0 | AT7: =SUM('Баллы без населения'!DR67:FK67,'Баллы без населения'!NW67:OL67) -> 0 | AU7: =SUM('Баллы без населения'!DL67:FK67) -> #REF! | AV7: =SUM('Баллы без населения'!DL67:DQ67) -> #REF! | AW7: =SUM('Баллы без населения'!DR67:DU67)+SUM('Баллы без населения'!DY67:ES67) -> 0 | AX7: =SUM('Баллы без населения'!DV67:DX67)+SUM('Баллы без населения'!ET67:FK67) -> 0 | AY7: =SUM('Баллы без населения'!DR67:DX67) -> 0 | AZ7: =SUM('Баллы без населения'!DR67:DU67) -> 0 | BA7: =SUM('Баллы без населения'!DV67:DX67) -> 0 | BB7: =SUM('Баллы без населения'!DY67:FK67) -> 0 | BC7: =SUM('Баллы без населения'!DY67:ES67) -> 0 | BD7: =SUM('Баллы без населения'!ET67:FK67) -> 0 | BE7: =SUM('Баллы без населения'!NW67:OL67) -> 0 | BF7: =SUMIF('Баллы без населения'!NW65:OL65,"муж",'Баллы без населения'!NW67:OL67) -> 0 | BG7: =SUMIF('Баллы без населения'!NW65:OL65,"жен",'Баллы без населения'!NW67:OL67) -> 0 | BH7: =SUM('Баллы без населения'!NW67:NZ67) -> 0 | BI7: =SUMIF('Баллы без населения'!NW65:NZ65,"муж",'Баллы без населения'!NW67:NZ67) -> 0 | BJ7: =SUMIF('Баллы без населения'!NW65:NZ65,";ty",'Баллы без населения'!NW67:NZ67) -> 0 | BK7: =SUM('Баллы без населения'!OA67:OL67) -> 0 | BL7: =SUMIF('Баллы без населения'!OA65:OL65,"муж",'Баллы без населения'!OA67:OL67) -> 0 | BM7: =SUMIF('Баллы без населения'!OA65:OL65,"муж",'Баллы без населения'!OA67:OL67) -> 0 | BN7: =SUM('Баллы без населения'!FL67:KE67,'Баллы'!OM67:PB67) -> #REF! | BO7: =SUM('Баллы без населения'!FL67:KE67) -> #REF! | BP7: =SUM('Баллы без населения'!FL67:FM67,'Баллы без населения'!FP67:FU67,'Баллы без населения'!GB67:GC67,'Баллы без населения'!GF67:GK67,'Баллы без населения'!GR67:GT67,'Баллы без населения'!GX67:HA67,'Баллы без населения'!HF67:HN67,'Баллы без населения'!HX67,'Баллы без населения'!HZ67:IB67,'Баллы без населения'!IX67,'Баллы без населения'!IF67:IH67,'Баллы без населения'!IL67:IQ67,'Баллы без населения'!IZ67:JE67,'Баллы без населения'!JH67:JY67,) -> #REF! | BQ7: =SUM('Баллы без населения'!FN67:FO67,'Баллы без населения'!FV67:GA67,'Баллы без населения'!GD67:GE67,'Баллы без населения'!GL67:GQ67,'Баллы без населения'!GU67:GW67,'Баллы без населения'!HB67:HE67,'Баллы без населения'!HO67:HW67,'Баллы без населения'!HY67,'Баллы без населения'!IC67:IE67,'Баллы без населения'!II67:IK67,'Баллы без населения'!IR67:IW67,'Баллы без населения'!IY67,'Баллы без населения'!JF67:JG67,'Баллы без населения'!JZ67:KE67) -> #REF! | BR7: =SUM('Баллы без населения'!FL67:FO67,'Баллы без населения'!GB67:GE67,'Баллы без населения'!GX67:HE67,'Баллы без населения'!IF67:IK67,'Баллы без населения'!IZ67:JG67) -> 0 | BS7: =SUM('Баллы без населения'!FL67:FM67,'Баллы без населения'!GB67:GC67,'Баллы без населения'!GX67:HA67,'Баллы без населения'!IZ67:JE67) -> 0 | BT7: =SUM('Баллы без населения'!FN67:FO67,'Баллы без населения'!GD67:GE67,'Баллы без населения'!HB67:HE67,'Баллы без населения'!II67:IK67,'Баллы без населения'!JF67:JG67) -> 0 | BU7: =SUM('Баллы без населения'!FP67:GA67,'Баллы без населения'!GF67:GQ67,'Баллы без населения'!HF67:HW67,'Баллы без населения'!IL67:IW67,'Баллы без населения'!JH67:KE67) -> 0 | BV7: =SUM('Баллы без населения'!FP67:FU67,'Баллы без населения'!GF67:GK67,'Баллы без населения'!HF67:HN67,'Баллы без населения'!IL67:IQ67,'Баллы без населения'!JH67:JY67) -> 0 | BW7: =SUM('Баллы без населения'!FV67:GA67,'Баллы без населения'!GL67:GQ67,'Баллы без населения'!HO67:HW67,'Баллы без населения'!IL67:IW67,'Баллы без населения'!JZ67:KE67) -> 0 | BX7: =SUM('Баллы без населения'!FL67:GA67) -> 0 | BY7: =SUM('Баллы без населения'!FL67:FM67,'Баллы без населения'!FP67:FU67) -> 0 | BZ7: =SUM('Баллы без населения'!FN67:FO67,'Баллы без населения'!FV67:GA67) -> 0 | CA7: =SUM('Баллы без населения'!GB67:GQ67) -> 0 | CB7: =SUM('Баллы без населения'!GB67:GC67,'Баллы без населения'!GF67:GK67) -> 0 | CC7: =SUM('Баллы без населения'!GD67:GE67,'Баллы без населения'!GL67:GQ67) -> 0 | CD7: =SUM('Баллы без населения'!GR67:HY67) -> #REF! | CE7: =SUM('Баллы без населения'!GR67:GT67,'Баллы без населения'!GX67:HA67,'Баллы без населения'!HF67:HN67,'Баллы без населения'!HX67) -> #REF! | CF7: =SUM('Баллы без населения'!GU67:GW67,'Баллы без населения'!HB67:HE67,'Баллы без населения'!HO67:HW67,'Баллы без населения'!HY67) -> #REF! | CG7: =SUM('Баллы без населения'!HZ67:IY67) -> 0 | CH7: =SUM('Баллы без населения'!HZ67:IB67,'Баллы без населения'!IF67:IH67,'Баллы без населения'!IL67:IQ67,'Баллы без населения'!IX67) -> 0 | CI7: =SUM('Баллы без населения'!IC67:IE67,'Баллы без населения'!II67:IK67,'Баллы без населения'!IR67:IW67,'Баллы без населения'!IY67) -> 0 | CJ7: =SUM('Баллы без населения'!IZ67:KE67,) -> 0 | CK7: =SUM('Баллы без населения'!IZ67:JE67,'Баллы без населения'!JH67:JY67) -> 0 | CL7: =SUM('Баллы без населения'!JF67:JG67,'Баллы без населения'!JZ67:KE67) -> 0 | CM7: =SUM('Баллы без населения'!OM67:PB67) -> 0 | CN7: =SUMIF('Баллы без населения'!OM65:PB65,"муж",'Баллы без населения'!OM67:PB67) -> 0 | CO7: =SUMIF('Баллы без населения'!OM65:PB65,"жен",'Баллы без населения'!OM67:PB67) -> 0 | CP7: =SUM('Баллы без населения'!OM67:OP67) -> 0 | CQ7: =SUMIF('Баллы без населения'!OM65:OP65,"муж",'Баллы без населения'!OM67:OP67) -> 0 | CR7: =SUMIF('Баллы без населения'!OM65:OP65,"жен",'Баллы без населения'!OM67:OP67) -> 0 | CS7: =SUM('Баллы без населения'!OQ67:PB67) -> 0 | CT7: =SUMIF('Баллы без населения'!OQ65:PB65,"муж",'Баллы без населения'!OQ67:PB67) -> 0 | CU7: =SUMIF('Баллы без населения'!OQ65:PB65,"жен",'Баллы без населения'!OQ67:PB67) -> 0 | CV7: =SUM('Баллы'!KF67:KU67,'Баллы'!PC67:PX67) -> 0 | CW7: =SUM('Баллы без населения'!KF67:KU67) -> 0 | CX7: =SUM('Баллы без населения'!PC67:PX67) -> 0 | CY7: =SUM('Баллы без населения'!KV67:LL67,'Баллы без населения'!PZ67:QJ67) -> 0 | CZ7: =SUM('Баллы без населения'!KZ67:LB67,'Баллы без населения'!PZ67:QJ67) -> 0 | DA7: =SUM('Баллы без населения'!KX67:KY67,'Баллы без населения'!LB67:LC67,'Баллы без населения'!LF67:LG67,'Баллы без населения'!QE67:QJ67) -> 0 | DB7: =SUM('Баллы без населения'!KX67:KY67,'Баллы без населения'!LB67:LC67,'Баллы без населения'!LF67:LG67,'Баллы без населения'!QE67:QG67) -> 0 | DC7: =SUM('Баллы без населения'!LC67,'Баллы без населения'!LG67,'Баллы без населения'!QH67:QJ67) -> 0 | DD7: =SUM('Баллы без населения'!KV67:LL67) -> 0 | DE7: =SUM('Баллы без населения'!KV67:KY67) -> 0 | DF7: =SUM('Баллы без населения'!KZ67:LG67) -> 0 | DG7: =SUM('Баллы без населения'!KZ67:LB67) -> 0 | DH7: =SUM('Баллы без населения'!LD67:LF67) -> 0 | DI7: =SUM('Баллы без населения'!KX67:KY67,'Баллы без населения'!LB67:LC67,'Баллы без населения'!LF67:LG67) -> 0 | DJ7: =SUM('Баллы без населения'!KX67:KY67) -> 0 | DK7: =SUM('Баллы без населения'!LB67:LC67,'Баллы без населения'!LF67:LG67) -> 0 | DL7: =SUM('Баллы без населения'!LC67,'Баллы без населения'!LG67) -> 0 | DM7: =SUM('Баллы без населения'!LH67:LL67) -> 0 | DN7: =SUM('Баллы без населения'!PY67:QJ67) -> 0 | DO7: =SUM('Баллы без населения'!PZ67,'Баллы без населения'!QB67:QJ67) -> 0 | DP7: =SUM('Баллы без населения'!QE67:QJ67) -> 0 | DQ7: =SUM('Баллы без населения'!QE67:QG67) -> 0 | DR7: =SUM('Баллы без населения'!QH67:QJ67) -> 0 | DS7: =SUM('Баллы без населения'!QK67:QP67) -> #REF! | DT7: =SUM('Баллы без населения'!QL67:QM67,'Баллы без населения'!QP67) -> 0 | DU7: =SUM('Баллы без населения'!QN67) -> 0 | DV7: =SUM('Баллы без населения'!QQ67:QX67) -> 0 | DW7: =SUM('Баллы без населения'!QQ67:QR67) -> 0 | DX7: =SUM('Баллы без населения'!QS67:QX67) -> 0
A8: 5 | B8: ='Тест ответы'!B51 -> Нижегородская область | C8: 1 | D8: ='Баллы без населения'!D50 -> #REF! | E8: =SUMIF('Баллы без населения'!$E$3:DX$3,"муж",'Баллы без населения'!E50:DX50) -> #REF! | F8: =SUMIF('Баллы без населения'!$E$3:DX$3,"жен",'Баллы без населения'!E50:DX50) -> #REF! | G8: =SUM('Баллы без населения'!Z50:DK50,'Баллы без населения'!DP50:KE50,'Баллы без населения'!KV50:LL50) -> #REF! | H8: =SUM('Баллы без населения'!LM50:PB50,'Баллы без населения'!PY50:QJ50) -> 0 | I8: =SUM('Баллы без населения'!AZ50:BO50,'Баллы без населения'!DR50:DX50,'Баллы без населения'!FL50:FO50,'Баллы без населения'!GB50:GE50,'Баллы без населения'!GX50:HE50,'Баллы без населения'!IF50:IK50,'Баллы без населения'!IZ50:JG50,'Баллы без населения'!LU50:MG50,'Баллы без населения'!NW50:NZ50,'Баллы без населения'!OM50:OP50) -> 0 | J8: =SUM('Баллы без населения'!BP50:DK50,'Баллы без населения'!DY50:FK50,'Баллы без населения'!FP50:GA50,'Баллы без населения'!GF50:GQ50,'Баллы без населения'!HF50:HW50,'Баллы без населения'!IL50:IW50,'Баллы без населения'!JH50:KE50,'Баллы без населения'!MH50:NV50,'Баллы без населения'!OA50:OL50,'Баллы без населения'!OQ50:PB50) -> 0 | K8: =SUM('Баллы без населения'!E50:R50) -> 0.1405 | L8: =SUM('Баллы без населения'!O50:R50) -> 0.09 | M8: =SUM('Баллы без населения'!S50:Y50) -> 0.1 | N8: =SUM('Баллы без населения'!T50:Y50) -> 0 | O8: =SUM('Баллы без населения'!Z50:AQ50,'Баллы без населения'!LM50:LT50) -> 0 | P8: =SUMIF('Баллы без населения'!$Z$3:$AQ$3,"муж",'Баллы без населения'!Z50:AQ50)+SUMIF('Баллы без населения'!$LM$3:$LT$3,"муж",'Баллы без населения'!LM50:LT50) -> 0 | Q8: =SUMIF('Баллы без населения'!$Z$3:$AQ$3,"жен",'Баллы без населения'!Z50:AQ50)+SUMIF('Баллы без населения'!$LM$3:$LT$3,"жен",'Баллы без населения'!LM50:LT50) -> 0 | R8: =SUM('Баллы без населения'!Z50:AQ50) -> 0 | S8: =SUM('Баллы без населения'!Z50:AH50) -> 0 | T8: =SUM('Баллы без населения'!AI50:AQ50) -> 0 | U8: =SUM('Баллы без населения'!LM50:LT50) -> 0 | V8: =SUM('Баллы без населения'!LM50:LP50) -> 0 | W8: =SUM('Баллы без населения'!LQ50:LT50) -> 0 | X8: =SUM('Баллы без населения'!AR50:DK50,'Баллы без населения'!LU50:NI50) -> 0 | Y8: ='Баллы без населения'!AR50+SUM('Баллы без населения'!AZ50:BH50)+SUM('Баллы без населения'!BP50:CP50)+SUM('Баллы без населения'!LU50:MC50,'Баллы без населения'!MH50:NI50) -> 0 | Z8: ='Баллы без населения'!AS50+SUM('Баллы без населения'!BI50:BO50)+SUM('Баллы без населения'!CQ50:DK50)+SUM('Баллы без населения'!MD50:MG50,'Баллы без населения'!NJ50:NV50,) -> 0 | AA8: =SUM('Баллы без населения'!AR50:DK50) -> 0 | AB8: =SUM('Баллы без населения'!AT50:AY50) -> 0 | AC8: ='Баллы без населения'!AR50+SUM('Баллы без населения'!AZ50:BH50)+SUM('Баллы без населения'!BP50:CP50) -> 0 | AD8: ='Баллы без населения'!AS50+SUM('Баллы без населения'!BI50:BO50)+SUM('Баллы без населения'!CQ50:DK50) -> 0 | AE8: =SUM('Баллы без населения'!AZ50:BO50) -> 0 | AF8: =SUM('Баллы без населения'!AZ50:BH50) -> 0 | AG8: =SUM('Баллы без населения'!BI50:BO50) -> 0 | AH8: =SUM('Баллы без населения'!BP50:DK50) -> 0 | AI8: =SUM('Баллы без населения'!BP50:CP50) -> 0 | AJ8: =SUM('Баллы без населения'!CQ50:DK50) -> 0 | AK8: =SUM('Баллы без населения'!LU50:NV50) -> 0 | AL8: =SUM('Баллы без населения'!LU50:MC50,'Баллы без населения'!MH50:NI50) -> 0 | AM8: =SUM('Баллы без населения'!MD50:MG50,'Баллы без населения'!NJ50:NV50,) -> 0 | AN8: =SUM('Баллы без населения'!LU50:MG50) -> 0 | AO8: =SUM('Баллы без населения'!LU50:MC50) -> 0 | AP8: =SUM('Баллы без населения'!MD50:MG50) -> 0 | AQ8: =SUM('Баллы без населения'!MH50:NV50) -> 0 | AR8: =SUM('Баллы без населения'!MH50:NI50) -> 0 | AS8: =SUM('Баллы без населения'!NJ50:NV50) -> 0 | AT8: =SUM('Баллы без населения'!DR50:FK50,'Баллы без населения'!NW50:OL50) -> 0 | AU8: =SUM('Баллы без населения'!DL50:FK50) -> #REF! | AV8: =SUM('Баллы без населения'!DL50:DQ50) -> #REF! | AW8: =SUM('Баллы без населения'!DR50:DU50)+SUM('Баллы без населения'!DY50:ES50) -> 0 | AX8: =SUM('Баллы без населения'!DV50:DX50)+SUM('Баллы без населения'!ET50:FK50) -> 0 | AY8: =SUM('Баллы без населения'!DR50:DX50) -> 0 | AZ8: =SUM('Баллы без населения'!DR50:DU50) -> 0 | BA8: =SUM('Баллы без населения'!DV50:DX50) -> 0 | BB8: =SUM('Баллы без населения'!DY50:FK50) -> 0 | BC8: =SUM('Баллы без населения'!DY50:ES50) -> 0 | BD8: =SUM('Баллы без населения'!ET50:FK50) -> 0 | BE8: =SUM('Баллы без населения'!NW50:OL50) -> 0 | BF8: =SUMIF('Баллы без населения'!NW48:OL48,"муж",'Баллы без населения'!NW50:OL50) -> 0 | BG8: =SUMIF('Баллы без населения'!NW48:OL48,"жен",'Баллы без населения'!NW50:OL50) -> 0 | BH8: =SUM('Баллы без населения'!NW50:NZ50) -> 0 | BI8: =SUMIF('Баллы без населения'!NW48:NZ48,"муж",'Баллы без населения'!NW50:NZ50) -> 0 | BJ8: =SUMIF('Баллы без населения'!NW48:NZ48,";ty",'Баллы без населения'!NW50:NZ50) -> 0 | BK8: =SUM('Баллы без населения'!OA50:OL50) -> 0 | BL8: =SUMIF('Баллы без населения'!OA48:OL48,"муж",'Баллы без населения'!OA50:OL50) -> 0 | BM8: =SUMIF('Баллы без населения'!OA48:OL48,"муж",'Баллы без населения'!OA50:OL50) -> 0 | BN8: =SUM('Баллы без населения'!FL50:KE50,'Баллы'!OM50:PB50) -> #REF! | BO8: =SUM('Баллы без населения'!FL50:KE50) -> #REF! | BP8: =SUM('Баллы без населения'!FL50:FM50,'Баллы без населения'!FP50:FU50,'Баллы без населения'!GB50:GC50,'Баллы без населения'!GF50:GK50,'Баллы без населения'!GR50:GT50,'Баллы без населения'!GX50:HA50,'Баллы без населения'!HF50:HN50,'Баллы без населения'!HX50,'Баллы без населения'!HZ50:IB50,'Баллы без населения'!IX50,'Баллы без населения'!IF50:IH50,'Баллы без населения'!IL50:IQ50,'Баллы без населения'!IZ50:JE50,'Баллы без населения'!JH50:JY50,) -> #REF! | BQ8: =SUM('Баллы без населения'!FN50:FO50,'Баллы без населения'!FV50:GA50,'Баллы без населения'!GD50:GE50,'Баллы без населения'!GL50:GQ50,'Баллы без населения'!GU50:GW50,'Баллы без населения'!HB50:HE50,'Баллы без населения'!HO50:HW50,'Баллы без населения'!HY50,'Баллы без населения'!IC50:IE50,'Баллы без населения'!II50:IK50,'Баллы без населения'!IR50:IW50,'Баллы без населения'!IY50,'Баллы без населения'!JF50:JG50,'Баллы без населения'!JZ50:KE50) -> #REF! | BR8: =SUM('Баллы без населения'!FL50:FO50,'Баллы без населения'!GB50:GE50,'Баллы без населения'!GX50:HE50,'Баллы без населения'!IF50:IK50,'Баллы без населения'!IZ50:JG50) -> 0 | BS8: =SUM('Баллы без населения'!FL50:FM50,'Баллы без населения'!GB50:GC50,'Баллы без населения'!GX50:HA50,'Баллы без населения'!IZ50:JE50) -> 0 | BT8: =SUM('Баллы без населения'!FN50:FO50,'Баллы без населения'!GD50:GE50,'Баллы без населения'!HB50:HE50,'Баллы без населения'!II50:IK50,'Баллы без населения'!JF50:JG50) -> 0 | BU8: =SUM('Баллы без населения'!FP50:GA50,'Баллы без населения'!GF50:GQ50,'Баллы без населения'!HF50:HW50,'Баллы без населения'!IL50:IW50,'Баллы без населения'!JH50:KE50) -> 0 | BV8: =SUM('Баллы без населения'!FP50:FU50,'Баллы без населения'!GF50:GK50,'Баллы без населения'!HF50:HN50,'Баллы без населения'!IL50:IQ50,'Баллы без населения'!JH50:JY50) -> 0 | BW8: =SUM('Баллы без населения'!FV50:GA50,'Баллы без населения'!GL50:GQ50,'Баллы без населения'!HO50:HW50,'Баллы без населения'!IL50:IW50,'Баллы без населения'!JZ50:KE50) -> 0 | BX8: =SUM('Баллы без населения'!FL50:GA50) -> 0 | BY8: =SUM('Баллы без населения'!FL50:FM50,'Баллы без населения'!FP50:FU50) -> 0 | BZ8: =SUM('Баллы без населения'!FN50:FO50,'Баллы без населения'!FV50:GA50) -> 0 | CA8: =SUM('Баллы без населения'!GB50:GQ50) -> 0 | CB8: =SUM('Баллы без населения'!GB50:GC50,'Баллы без населения'!GF50:GK50) -> 0 | CC8: =SUM('Баллы без населения'!GD50:GE50,'Баллы без населения'!GL50:GQ50) -> 0 | CD8: =SUM('Баллы без населения'!GR50:HY50) -> #REF! | CE8: =SUM('Баллы без населения'!GR50:GT50,'Баллы без населения'!GX50:HA50,'Баллы без населения'!HF50:HN50,'Баллы без населения'!HX50) -> #REF! | CF8: =SUM('Баллы без населения'!GU50:GW50,'Баллы без населения'!HB50:HE50,'Баллы без населения'!HO50:HW50,'Баллы без населения'!HY50) -> #REF! | CG8: =SUM('Баллы без населения'!HZ50:IY50) -> 0 | CH8: =SUM('Баллы без населения'!HZ50:IB50,'Баллы без населения'!IF50:IH50,'Баллы без населения'!IL50:IQ50,'Баллы без населения'!IX50) -> 0 | CI8: =SUM('Баллы без населения'!IC50:IE50,'Баллы без населения'!II50:IK50,'Баллы без населения'!IR50:IW50,'Баллы без населения'!IY50) -> 0 | CJ8: =SUM('Баллы без населения'!IZ50:KE50,) -> 0 | CK8: =SUM('Баллы без населения'!IZ50:JE50,'Баллы без населения'!JH50:JY50) -> 0 | CL8: =SUM('Баллы без населения'!JF50:JG50,'Баллы без населения'!JZ50:KE50) -> 0 | CM8: =SUM('Баллы без населения'!OM50:PB50) -> 0 | CN8: =SUMIF('Баллы без населения'!OM48:PB48,"муж",'Баллы без населения'!OM50:PB50) -> 0 | CO8: =SUMIF('Баллы без населения'!OM48:PB48,"жен",'Баллы без населения'!OM50:PB50) -> 0 | CP8: =SUM('Баллы без населения'!OM50:OP50) -> 0 | CQ8: =SUMIF('Баллы без населения'!OM48:OP48,"муж",'Баллы без населения'!OM50:OP50) -> 0 | CR8: =SUMIF('Баллы без населения'!OM48:OP48,"жен",'Баллы без населения'!OM50:OP50) -> 0 | CS8: =SUM('Баллы без населения'!OQ50:PB50) -> 0 | CT8: =SUMIF('Баллы без населения'!OQ48:PB48,"муж",'Баллы без населения'!OQ50:PB50) -> 0 | CU8: =SUMIF('Баллы без населения'!OQ48:PB48,"жен",'Баллы без населения'!OQ50:PB50) -> 0 | CV8: =SUM('Баллы'!KF50:KU50,'Баллы'!PC50:PX50) -> 0 | CW8: =SUM('Баллы без населения'!KF50:KU50) -> 0 | CX8: =SUM('Баллы без населения'!PC50:PX50) -> 0 | CY8: =SUM('Баллы без населения'!KV50:LL50,'Баллы без населения'!PZ50:QJ50) -> 0 | CZ8: =SUM('Баллы без населения'!KZ50:LB50,'Баллы без населения'!PZ50:QJ50) -> 0 | DA8: =SUM('Баллы без населения'!KX50:KY50,'Баллы без населения'!LB50:LC50,'Баллы без населения'!LF50:LG50,'Баллы без населения'!QE50:QJ50) -> 0 | DB8: =SUM('Баллы без населения'!KX50:KY50,'Баллы без населения'!LB50:LC50,'Баллы без населения'!LF50:LG50,'Баллы без населения'!QE50:QG50) -> 0 | DC8: =SUM('Баллы без населения'!LC50,'Баллы без населения'!LG50,'Баллы без населения'!QH50:QJ50) -> 0 | DD8: =SUM('Баллы без населения'!KV50:LL50) -> 0 | DE8: =SUM('Баллы без населения'!KV50:KY50) -> 0 | DF8: =SUM('Баллы без населения'!KZ50:LG50) -> 0 | DG8: =SUM('Баллы без населения'!KZ50:LB50) -> 0 | DH8: =SUM('Баллы без населения'!LD50:LF50) -> 0 | DI8: =SUM('Баллы без населения'!KX50:KY50,'Баллы без населения'!LB50:LC50,'Баллы без населения'!LF50:LG50) -> 0 | DJ8: =SUM('Баллы без населения'!KX50:KY50) -> 0 | DK8: =SUM('Баллы без населения'!LB50:LC50,'Баллы без населения'!LF50:LG50) -> 0 | DL8: =SUM('Баллы без населения'!LC50,'Баллы без населения'!LG50) -> 0 | DM8: =SUM('Баллы без населения'!LH50:LL50) -> 0 | DN8: =SUM('Баллы без населения'!PY50:QJ50) -> 0 | DO8: =SUM('Баллы без населения'!PZ50,'Баллы без населения'!QB50:QJ50) -> 0 | DP8: =SUM('Баллы без населения'!QE50:QJ50) -> 0 | DQ8: =SUM('Баллы без населения'!QE50:QG50) -> 0 | DR8: =SUM('Баллы без населения'!QH50:QJ50) -> 0 | DS8: =SUM('Баллы без населения'!QK50:QP50) -> #REF! | DT8: =SUM('Баллы без населения'!QL50:QM50,'Баллы без населения'!QP50) -> 0 | DU8: =SUM('Баллы без населения'!QN50) -> 0 | DV8: =SUM('Баллы без населения'!QQ50:QX50) -> 0 | DW8: =SUM('Баллы без населения'!QQ50:QR50) -> 0 | DX8: =SUM('Баллы без населения'!QS50:QX50) -> 0
